Workbook

Sheet Paper Comparison
A1: Comparison of our deepfake detector with 6 prior works (deepfake detection + adversarial robustness)
A2: Only our work reports Precision/Recall/F1 per class; most papers report AUC or accuracy, and protocols differ - see 'Metrics Side-by-Side' and 'Sources & Notes' before comparing numbers directly.
A3: # | B3: Paper | C3: Dataset(s) & protocol | D3: Model / architecture | E3: Training technique | F3: Attack / defense | G3: Key reported results | H3: Where they are better than ours | I3: Their limitations | J3: What we take from it (to improve ours) | K3: Source | L3: Verification
A4: OURS | B4: OURS - ResNet18 deepfake detector + FGSM/PGD robustness sweep (this project) | C4: FaceForensics++ frame subset (own extraction). Split by source video (check pair-level leakage). Current test = 1,200 frames (600 real / 600 fake). Full 224x224 frames, no face crop. Frame-level. | D4: ResNet18 (ImageNet-pretrained), final FC replaced with 2 classes. | E4: Adam, lr 1e-4, batch 32, 10 epochs, no scheduler. Aug: flip + light colour jitter. Best checkpoint by val accuracy. | F4: Attack evaluation only: FGSM and PGD (7 steps, alpha 0.01), eps 0 to 0.1 in [0,1] pixel space. No defense. | G4: Current run: Acc 80.08%, Precision (macro) 80.73%, Recall (macro) 80.08%, F1 (macro) 80.0%, Specificity 72.83%, Fake recall 87.33%, AUC 84.9%. Earlier run (92.6% ckpt): PGD acc 4.18% at eps 0.005, 0.09% at eps 0.01, 0% from eps 0.02; FGSM 10.7% at eps 0.01 - re-run on current ckpt. | H4: - | I4: Plain CNN backbone; full-frame input (no face crop); likely undertrained (earlier run val acc still rising at epoch 10); single dataset, no cross-dataset test; no adversarial training; detector collapses at eps ~2.6/255. Biased to flagging real as fake (163 FP vs 76 FN). | J4: - | K4: metrics.json, robustness_results.csv, train_log.csv | L4: Our own run files
A5: 1 | B5: Rossler et al., 'FaceForensics++: Learning to Detect Manipulated Facial Images', ICCV 2019 | C5: FF++: 1,000 real YouTube videos + 4 manipulations (DeepFakes, Face2Face, FaceSwap, NeuralTextures); raw / c23 (HQ) / c40 (LQ). Frame-level on face crops. | D5: XceptionNet (ImageNet-pretrained); MesoNet and others as baselines. | E5: Transfer learning on face crops from a face tracker; trained per manipulation / compression level. | F5: None (no adversarial evaluation). | G5: XceptionNet HQ accuracy: DF 97.49, F2F 97.69, FS 96.79, NT 92.19 (avg ~96.0%). MesoNet avg ~84.0%. | H5: Face-cropped input; stronger backbone (Xception); standard benchmark with per-manipulation and per-compression results. | I5: No robustness evaluation; per-manipulation training generalises poorly to unseen methods; 2019 baselines. | J5: Add face detection + alignment; report per-manipulation and c23/c40 results so our number is comparable to the benchmark. | K5: arXiv:1901.08971; github.com/ondyari/FaceForensics | L5: Numbers taken from Table 1 of Hussain et al. (secondary) - check against original
A6: 2 | B6: Hussain, Neekhara et al., 'Adversarial Deepfakes: Evaluating Vulnerability of Deepfake Detectors to Adversarial Examples', WACV 2021 | C6: FF++ HQ test set (70 videos x 4 methods, 29,764 frames) for Xception/MesoNet; DFDC validation (200 fake videos) for a 3D-CNN. | D6: Victims: XceptionNet, MesoNet, 3D-EfficientNet sequence model (DFDC 3rd place). | E6: Attack paper (no new detector trained). | F6: White-box: iterative sign method, eps 16/255, up to 100 iters, logit-margin loss. Robust white-box: Expectation over Transforms (blur, noise, shift, resize). Black-box: NES query attack. | G6: White-box success 99.85% (Xception) / 98.15% (MesoNet) on raw video. Robust white-box on compressed video: detector accuracy 1.77% (Xception), 0.50% (MesoNet). 3D-CNN: 91.74% clean -> 0.00%. Robust black-box: detector accuracy 16.06% / 21.67%. | H6: Realistic threat model: perturbations survive JPEG/H.264 compression; black-box variant; video pipeline; tests a temporal model too. | I6: Attack only - proposes no defense (just recommends adversarial training); L-inf only; older detectors; fake->real direction only; expensive (up to 100 iters/frame, ~1k-2k queries/frame black-box). | J6: Add compression-robust (EOT) and black-box transfer tests to our attack suite. Our PGD already breaks the model, but only in the ideal uncompressed white-box case. | K6: arXiv:2002.12749; WACV 2021 pp. 3348-3357 | L6: Verified from paper full text
A7: 3 | B7: Khan, Chen, Liao, Chen, 'Adversarially Robust Deepfake Detection via Adversarial Feature Similarity Learning' (AFSL), LNCS 14556, 2024 | C7: FF++ c23 (1,000 real / 4,000 fake), train on 3 manipulations, test on 4th; unseen: FaceShifter, DeeperForensics. Video-level AUC and frame-level accuracy. | D7: RealForensics (CSN, self-supervised pretrained), XceptionNet, MesoNet. | E7: PGD-5 adversarial training + 3-part loss: logit-adjusted BCE + adversarial cosine-similarity loss + real/fake dissimilarity regulariser (beta 1 and 0.1). Adam lr 3e-4 (video) / SGD lr 2e-3, bs 16 (frame), 150 epochs. | F7: Defense. Tested vs PGD10, CW2, StatAttack, universal attack, robust white-box, robust black-box. | G7: RealForensics: clean AUC 91.5 -> 1.1 under PGD10 (8/255). With AFSL: 89.8 clean -> 80.7 under PGD10. Frame-level Xception accuracy under PGD10: 7.3% (undefended) -> 81.7% (AFSL); MesoNet 6.2% -> 79.5%. Beats vanilla PGD-AT (76.0 / 74.3) and TRADES (80.8 / 78.2). | H7: Actually defends: keeps most clean performance while recovering ~80% under PGD10. Multiple attack types. Closest paper to our title. | I7: ~1.7-pt clean AUC cost vs undefended RealForensics; heavy training (PGD-AT, 150 epochs); FaceShifter / DeeperForensics are built on FF++ real videos so domain shift is limited; baselines re-run (lower than their papers); no AutoAttack. | J7: Implement PGD-AT -> TRADES -> AFSL loss on our model and show the same before/after robustness curve. This is the main gap to close. | K7: arXiv:2403.08806 | L7: Verified from paper full text (Tables 1-5)
A8: 4 | B8: Shiohara & Yamasaki, 'Detecting Deepfakes with Self-Blended Images' (SBI), CVPR 2022 (Oral) | C8: Train on FF++; test on CDF, DFD, DFDC, DFDCP, FFIW (cross-dataset) and cross-manipulation. Frame-level AUC. | D8: EfficientNet-B4 classifier. | E8: Trains only on real images + synthetic 'self-blended' fakes (blend slightly altered copies of one real face) with source/target augmentation. No real fakes needed. | F8: None (no adversarial evaluation). | G8: Cross-dataset AUC: Celeb-DF 93.18%. Average frame-level AUC 87.33% vs 82.75% for the comparison baseline (+4.58 pts). Beats prior frame-level SOTA on CDF/DFDC/DFDCP by 6.08 / 5.17 / 5.23 pts. | H8: Far better generalisation to unseen datasets and manipulations; data-centric training trick, not a bigger model. | I8: Assumes blending-boundary artifacts, so less suited to fully generated faces; needs landmark/face preprocessing; no robustness evaluation. | J8: Add SBI-style synthetic fakes as extra training data (public code) and test cross-dataset on Celeb-DF / DFD. | K8: arXiv:2204.08376; github.com/mapooon/SelfBlendedImages | L8: Paper text verified; Celeb-DF 93.18 from secondary leaderboard
A9: 5 | B9: Yan et al., 'Orthogonal Subspace Decomposition for Generalizable AI-Generated Image Detection' (Effort), ICML 2025 | C9: Train on FF++, test on 7 unseen deepfake datasets; also DF40 and synthetic-image benchmarks. | D9: CLIP vision transformer (vision foundation model). | E9: SVD splits CLIP weights into principal (frozen, semantic) and residual (trained, forgery) subspaces; only ~0.19M trainable parameters. | F9: None reported in the summaries accessed (focus is generalisation). | G9: Cross-dataset average AUC 0.917 (FF++ -> 7 unseen datasets), outperforming 13 baselines; 0.940 AUC on DF40. | H9: State-of-the-art generalisation with tiny trainable-parameter budget; foundation-model features instead of a small CNN. | I9: Large ViT backbone -> heavier inference than ResNet18; adversarial robustness not the paper's focus; depends on CLIP pretraining data. | J9: Replace ResNet18 with a CLIP/ViT backbone using parameter-efficient (SVD / LoRA) fine-tuning, then test its adversarial robustness - an open gap. | K9: arXiv:2411.15633; github.com/YZY-stack/Effort-AIGI-Detection | L9: Abstract verified; AUC figures from secondary summary - check paper tables
A10: 6 | B10: Chandra et al., 'Deepfake-Eval-2024: A Multi-Modal In-the-Wild Benchmark of Deepfakes Circulated in 2024', 2025 | C10: ~45 h video, 56.5 h audio, 1,975 images collected in 2024 from social media and a detection platform (88 sites, 52 languages). | D10: Evaluates open-source SOTA detectors, commercial detectors, and fine-tuned models. | E10: Fine-tuning open-source models on the new in-the-wild data improves them. | F10: None (distribution-shift benchmark). | G10: Open-source detector AUC drops ~50% (video), 48% (audio), 45% (image) vs older benchmarks; commercial/fine-tuned models do better but still trail human forensic analysts. | H10: Tests on real-world, current deepfakes rather than FF++-style academic data. | I10: A benchmark, not a method; in-the-wild labels/data access constraints. | J10: Our 92.6% on FF++ will not carry over to the wild: add a cross-dataset test and state this as a threat to validity. | K10: arXiv:2503.02857 | L10: Verified from abstract

Sheet Metrics Side-by-Side
A1: Numeric comparison (percent). Protocols differ - read the last column before comparing rows.
A2: Blue = typed from the paper. Green = linked from 'Our Model'. Black = formula. n/r = not reported. eps shown in /255 units.
A4: Model / paper | B4: Backbone | C4: Dataset & protocol | D4: Headline metric | E4: Clean % | F4: Precision % | G4: Recall % | H4: F1 % | I4: Attack (eps) | J4: Under attack % | K4: Drop (pts) | L4: Comparability note
A5: OURS - clean / FGSM | B5: ResNet18 | C5: FF++ frames, own video-level split, frame-level | D5: Accuracy | E5: ='Our Model'!B11*100 -> 80.083333 | F5: ='Our Model'!B18*100 -> 80.729419 | G5: ='Our Model'!B19*100 -> 80.083333 | H5: ='Our Model'!B20*100 -> 79.978093 | I5: FGSM, eps 0.03 (~7.7/255) | J5: ='Our Model'!C30*100 -> 22.524977 | K5: =('Our Model'!C26-'Our Model'!C30)*100 -> 70.118074 | L5: Clean = current ckpt (80.1%); FGSM number and drop are from the earlier 92.6% ckpt. Re-run attacks.py. Small test set (1,200 frames). P/R/F1 macro.
A6: OURS - clean / PGD | B6: ResNet18 | C6: FF++ frames, own video-level split, frame-level | D6: Accuracy | E6: ='Our Model'!B11*100 -> 80.083333 | F6: ='Our Model'!B18*100 -> 80.729419 | G6: ='Our Model'!B19*100 -> 80.083333 | H6: ='Our Model'!B20*100 -> 79.978093 | I6: PGD-7, eps 0.03 (~7.7/255) | J6: ='Our Model'!D30*100 -> 0 | K6: =('Our Model'!D26-'Our Model'!D30)*100 -> 92.643052 | L6: Clean = current ckpt; PGD number/drop from earlier ckpt. Closest eps we ran to 8/255. PGD-7 without random start.
A7: FF++ paper - XceptionNet (HQ/c23) | B7: XceptionNet | C7: FF++ HQ test, 4 manipulations, face crops | D7: Accuracy | E7: =AVERAGE(97.49,97.69,96.79,92.19) -> 96.04 | F7: n/r | G7: n/r | H7: n/r | I7: none | J7: n/r | K7: =IF(AND(ISNUMBER(E7),ISNUMBER(J7)),E7-J7,"n/a") -> n/a | L7: Average of the 4 per-manipulation accuracies (our calculation). Trained per manipulation, so easier than our mixed task.
A8: FF++ paper - MesoNet (HQ/c23) | B8: MesoNet | C8: FF++ HQ test, 4 manipulations, face crops | D8: Accuracy | E8: =AVERAGE(89.55,88.6,81.24,76.62) -> 84.0025 | F8: n/r | G8: n/r | H8: n/r | I8: none | J8: n/r | K8: =IF(AND(ISNUMBER(E8),ISNUMBER(J8)),E8-J8,"n/a") -> n/a | L8: Average of the 4 per-manipulation accuracies (our calculation).
A9: Hussain et al. - Xception under robust white-box | B9: XceptionNet | C9: FF++ HQ test, compressed (MJPEG) adversarial videos | D9: Accuracy | E9: =E7 -> 96.04 | F9: n/r | G9: n/r | H9: n/r | I9: Robust white-box, eps<=16/255 (mean L-inf 0.013 = ~3.3/255) | J9: 1.77 | K9: =IF(AND(ISNUMBER(E9),ISNUMBER(J9)),E9-J9,"n/a") -> 94.27 | L9: Attack on compressed video; mean perturbation only ~3.3/255. Clean value is the FF++ average above.
A10: Hussain et al. - MesoNet under robust white-box | B10: MesoNet | C10: FF++ HQ test, compressed (MJPEG) adversarial videos | D10: Accuracy | E10: =E8 -> 84.0025 | F10: n/r | G10: n/r | H10: n/r | I10: Robust white-box, eps<=16/255 (mean L-inf 0.025 = ~6.4/255) | J10: 0.5 | K10: =IF(AND(ISNUMBER(E10),ISNUMBER(J10)),E10-J10,"n/a") -> 83.5025 | L10: Clean value is the FF++ average above.
A11: AFSL paper - Xception, undefended | B11: XceptionNet | C11: FF++ c23, frame-level | D11: Accuracy | E11: n/r | F11: n/r | G11: n/r | H11: n/r | I11: PGD10, 8/255 | J11: 7.3 | K11: =IF(AND(ISNUMBER(E11),ISNUMBER(J11)),E11-J11,"n/a") -> n/a | L11: Same kind of result as ours (accuracy, frame-level, PGD): undefended frame models collapse.
A12: AFSL paper - Xception + AFSL | B12: XceptionNet | C12: FF++ c23, frame-level | D12: Accuracy | E12: n/r | F12: n/r | G12: n/r | H12: n/r | I12: PGD10, 8/255 | J12: 81.7 | K12: =IF(AND(ISNUMBER(E12),ISNUMBER(J12)),E12-J12,"n/a") -> n/a | L12: Defended model keeps ~82% under PGD10 - the target for our adversarial-training step.
A13: AFSL paper - RealForensics, undefended | B13: RealForensics (CSN) | C13: FF++ c23, train 3 / test 4th manipulation, video-level | D13: AUC | E13: 91.5 | F13: n/r | G13: n/r | H13: n/r | I13: PGD10, 8/255 | J13: 1.1 | K13: =IF(AND(ISNUMBER(E13),ISNUMBER(J13)),E13-J13,"n/a") -> 90.4 | L13: Video-level AUC, cross-manipulation: not directly comparable to our frame accuracy.
A14: AFSL paper - RealForensics + AFSL | B14: RealForensics (CSN) | C14: FF++ c23, train 3 / test 4th manipulation, video-level | D14: AUC | E14: 89.8 | F14: n/r | G14: n/r | H14: n/r | I14: PGD10, 8/255 | J14: 80.7 | K14: =IF(AND(ISNUMBER(E14),ISNUMBER(J14)),E14-J14,"n/a") -> 9.1 | L14: Clean AUC cost of the defense is ~1.7 pts; robust AUC is 80.7.
A15: SBI (CVPR 2022) | B15: EfficientNet-B4 | C15: Train FF++, test Celeb-DF, frame-level | D15: AUC | E15: 93.18 | F15: n/r | G15: n/r | H15: n/r | I15: none | J15: n/r | K15: =IF(AND(ISNUMBER(E15),ISNUMBER(J15)),E15-J15,"n/a") -> n/a | L15: Cross-dataset AUC (not in-domain). Our model has no cross-dataset number yet.
A16: Effort (ICML 2025) | B16: CLIP ViT | C16: Train FF++, avg over 7 unseen datasets | D16: AUC | E16: 91.7 | F16: n/r | G16: n/r | H16: n/r | I16: none | J16: n/r | K16: =IF(AND(ISNUMBER(E16),ISNUMBER(J16)),E16-J16,"n/a") -> n/a | L16: Average cross-dataset AUC (0.917). Generalisation metric, not in-domain accuracy.
A18: Read-out
A19: 1) Current in-domain clean accuracy (ours 80.1%, AUC 0.849) is BELOW published FF++ frame-level numbers (~92-98%), though those use face crops and per-manipulation training. Earlier run reported 92.6% - find out which split/run is the real one.
A20: 2) Under PGD every undefended model collapses to near 0-8% - ours included. Only adversarially trained models (AFSL, TRADES) hold ~75-82%.
A21: 3) No cross-dataset number for our model; SBI / Effort show that is where modern methods differ most. Attack numbers must be re-run on the current checkpoint.

Sheet Improvement Plan
A1: How to make our model better (ordered by impact for the paper)
A3: Priority | B3: Gap in our model | C3: Fix (latest technique) | D3: Based on | E3: Expected effect | F3: Effort | G3: How we will show it
A4: 1 | B4: No defense: PGD takes accuracy to ~0% at eps ~2.6/255. | C4: PGD adversarial training (Madry), then TRADES, then AFSL-style loss (cross-entropy + adversarial feature-similarity + real/fake regulariser). | D4: Khan et al. 2024 (AFSL); Madry et al. 2018; Zhang et al. 2019 (TRADES) | E4: Robust accuracy from ~0% to the ~75-82% range seen for defended Xception under PGD10. | F4: Medium | G4: Re-run attacks.py on the defended model; plot clean vs robust curve next to the current one.
A5: 2 | B5: Weak backbone for a journal paper (plain ResNet18). | C5: ViT/CLIP backbone with parameter-efficient fine-tuning (SVD-orthogonal as in Effort, or LoRA); fallback: EfficientNet-B4 / ConvNeXt. | D5: Yan et al. 2025 (Effort); Shiohara 2022 (EfficientNet-B4) | E5: Better cross-dataset generalisation; new question: are foundation-model detectors more or less adversarially robust? | F5: High | G5: Same pipeline, swap model.py; compare ResNet18 vs EfficientNet vs CLIP.
A6: 3 | B6: Evaluation is too easy: one dataset, no cross-dataset test. | C6: Cross-dataset tests (Celeb-DF v2, DFDC, DFD) and cross-manipulation; use only official/authorised dataset sources. | D6: Shiohara 2022; Chandra et al. 2025 | E6: Honest generalisation numbers; avoids overclaiming in-domain accuracy. | F6: Medium | G6: AUC table: train FF++, test on each unseen set.
A7: 4 | B7: Full frames, no face crop. | C7: Face detection + alignment (e.g. RetinaFace / MTCNN) before resize; margin around face. | D7: Rossler et al. 2019; Hussain et al. 2021 | E7: Removes background shortcuts; typically higher accuracy. | F7: Low | G7: Re-train with crops; compare to full-frame result.
A8: 5 | B8: Training recipe is basic (10 epochs, constant lr, val acc still rising). | C8: AdamW + cosine decay with warm-up, label smoothing, mixed precision, EMA of weights, 20-30 epochs with early stopping. | D8: Standard modern recipe | E8: Higher clean accuracy at lower cost; fixes undertraining. | F8: Low | G8: Training curves with converged val loss.
A9: 6 | B9: Training data has only the fake types in the dataset. | C9: Add self-blended-image (SBI) synthetic fakes plus JPEG / blur / resize augmentation. | D9: Shiohara & Yamasaki 2022 | E9: Better generalisation to unseen manipulations and compressed video. | F9: Medium | G9: Ablation: with / without SBI on cross-dataset AUC.
A10: 7 | B10: Attack suite is narrow (FGSM, 7-step PGD, no random start). | C10: PGD with random start and 20-50 steps, eps 2/255, 4/255, 8/255; AutoAttack (APGD-CE, APGD-T); margin (CW) loss; black-box transfer; EOT with JPEG/resize. | D10: Hussain et al. 2021; Khan et al. 2024 | E10: Stronger, standard worst-case numbers; rules out gradient-masking claims. | F10: Medium | G10: Robust accuracy at fixed eps (4/255, 8/255) for every model.
A11: 8 | B11: FGSM accuracy rises again at large eps (10.7% -> 46.7%). | C11: Report PGD as the main robustness number; explain FGSM overshoot; add a larger-step-count check. | D11: Our robustness_results.csv | E11: Prevents a reviewer reading the FGSM curve as 'the model gets more robust'. | F11: Low | G11: One sentence + plot with PGD emphasised.
A12: 9 | B12: Frame-level only; point estimates only. | C12: Video-level aggregation (mean of frame probabilities), AUC / EER, 3 seeds with confidence intervals. | D12: Khan et al. 2024 (video-level AUC) | E12: Comparable to the literature's metrics; statistical weight. | F12: Low | G12: Mean +/- std over 3 seeds.
A13: 10 | B13: Possible leakage between real videos and the fakes made from them (a leak-free split may explain 92.6% -> 80.1% between runs). | C13: Split by source identity / video pair (a real video and all fakes derived from it go to the same split). Check how video_id is built from filenames. | D13: FF++ dataset structure | E13: Cleaner test set; avoids inflated accuracy. | F13: Low | G13: Dataset information file showing pair-level split.

Sheet Our Model
A1: Our model: ResNet18 deepfake detector (FF++ frames) - current test results (confusion matrix + ROC images); attack/training tables are from the EARLIER run
A2: Blue = typed in from result images / old run files. Black = formula. Green = link to another sheet.
A4: Confusion matrix (test) | B4: Pred real | C4: Pred fake
A5: True real | B5: 437 | C5: 163
A6: True fake | B6: 76 | C6: 524
A7: Source: resnet18_confusion_matrix.png (current run, 1,200 test frames = 600 real / 600 fake). Rows = true class, columns = predicted class.
A9: Metric | B9: Computed (formula) | C9: Earlier run (old metrics.json) | D9: Change vs earlier run
A10: Test samples | B10: =SUM(B5:C6) -> 1200 | C10: 1101 | D10: =B10-C10 -> 99
A11: Accuracy | B11: =(B5+C6)/SUM(B5:C6) -> 0.80083333 | C11: 0.92643052 | D11: =B11-C11 -> -0.12559718
A12: Precision - fake class | B12: =C6/(C6+C5) -> 0.76273654
A13: Recall - fake class | B13: =C6/(C6+B6) -> 0.87333333
A14: F1 - fake class | B14: =2*B12*B13/(B12+B13) -> 0.81429681
A15: Precision - real class | B15: =B5/(B5+B6) -> 0.85185185
A16: Recall - real class (= specificity) | B16: =B5/(B5+C5) -> 0.72833333 | C16: 0.90466926 | D16: =B16-C16 -> -0.17633593
A17: F1 - real class | B17: =2*B15*B16/(B15+B16) -> 0.78526505
A18: Precision (macro) | B18: =AVERAGE(B12,B15) -> 0.80729419 | C18: 0.92724393 | D18: =B18-C18 -> -0.11994973
A19: Recall (macro) | B19: =AVERAGE(B13,B16) -> 0.80083333 | C19: 0.92507739 | D19: =B19-C19 -> -0.12424406
A20: F1 (macro) | B20: =AVERAGE(B14,B17) -> 0.79978093 | C20: 0.92593562 | D20: =B20-C20 -> -0.12615468
A21: ROC AUC (current: read from ROC plot, 3 d.p.) | B21: 0.849 | C21: 0.98163848 | D21: =B21-C21 -> -0.13263848
A24: Adversarial robustness - EARLIER-RUN checkpoint (clean acc 92.6%); NOT the current 80.1% model - re-run attacks before quoting
A25: Epsilon (0-1 scale) | B25: Epsilon in /255 units | C25: FGSM accuracy | D25: PGD accuracy | E25: FGSM drop (pts) | F25: PGD drop (pts)
A26: 0 | B26: =A26*255 -> 0 | C26: 0.92643052 | D26: 0.92643052 | E26: =($C$26-C26)*100 -> 0 | F26: =($D$26-D26)*100 -> 0
A27: 0.005 | B27: =A27*255 -> 1.275 | C27: 0.1671208 | D27: 0.0417802 | E27: =($C$26-C27)*100 -> 75.930972 | F27: =($D$26-D27)*100 -> 88.465032
A28: 0.01 | B28: =A28*255 -> 2.55 | C28: 0.1071753 | D28: 0.00090826521 | E28: =($C$26-C28)*100 -> 81.925522 | F28: =($D$26-D28)*100 -> 92.552225
A29: 0.02 | B29: =A29*255 -> 5.1 | C29: 0.16893733 | D29: 0 | E29: =($C$26-C29)*100 -> 75.749319 | F29: =($D$26-D29)*100 -> 92.643052
A30: 0.03 | B30: =A30*255 -> 7.65 | C30: 0.22524977 | D30: 0 | E30: =($C$26-C30)*100 -> 70.118074 | F30: =($D$26-D30)*100 -> 92.643052
A31: 0.05 | B31: =A31*255 -> 12.75 | C31: 0.40145322 | D31: 0 | E31: =($C$26-C31)*100 -> 52.497729 | F31: =($D$26-D31)*100 -> 92.643052
A32: 0.1 | B32: =A32*255 -> 25.5 | C32: 0.46684832 | D32: 0 | E32: =($C$26-C32)*100 -> 45.95822 | F32: =($D$26-D32)*100 -> 92.643052
A33: Source: robustness_results.csv. PGD = 7 steps, alpha 0.01, no random start. Literature usually reports eps = 8/255 (=0.031) or 16/255 (=0.063). STALE: eps-0 accuracy here (92.6%) does not match the current model (80.1%).
A34: Observation: FGSM accuracy RISES again for eps > 0.01 (10.7% -> 46.7%) while PGD stays at ~0%. Single-step FGSM overshoots at large eps; PGD is the reliable worst-case number.
A36: Training log (train_log.csv) - earlier run
A37: Epoch | B37: Train loss | C37: Val loss | D37: Train acc | E37: Val acc | F37: Train - val acc (pts)
A38: 1 | B38: 0.44384637 | C38: 0.43055418 | D38: 0.78541374 | E38: 0.80675105 | F38: =(D38-E38)*100 -> -2.133731
A39: 2 | B39: 0.34315819 | C39: 0.46244311 | D39: 0.8434432 | E39: 0.80337553 | F39: =(D39-E39)*100 -> 4.006767
A40: 3 | B40: 0.28343953 | C40: 0.37851902 | D40: 0.87535063 | E40: 0.82109705 | F40: =(D40-E40)*100 -> 5.4253585
A41: 4 | B41: 0.24311568 | C41: 0.33366591 | D41: 0.89200561 | E41: 0.83291139 | F41: =(D41-E41)*100 -> 5.9094218
A42: 5 | B42: 0.2120229 | C42: 0.27276074 | D42: 0.90550491 | E42: 0.85822785 | F42: =(D42-E42)*100 -> 4.7277061
A43: 6 | B43: 0.17840164 | C43: 0.26079188 | D43: 0.91988079 | E43: 0.86329114 | F43: =(D43-E43)*100 -> 5.6589646
A44: 7 | B44: 0.1531423 | C44: 0.24239485 | D44: 0.92689341 | E44: 0.88523207 | F44: =(D44-E44)*100 -> 4.1661341
A45: 8 | B45: 0.14211271 | C45: 0.23393774 | D45: 0.93267882 | E45: 0.88776371 | F45: =(D45-E45)*100 -> 4.4915109
...

Sheet Sources & Notes
A1: Sources, caveats and what to double-check before presenting
A3: Item | B3: Detail
A4: Our numbers | B4: Current-run metrics (confusion matrix, AUC) are read from resnet18_confusion_matrix.png and resnet18_roc_curve.png. Attack and training-log tables come from the earlier run files and are flagged stale.
A5: Comparability | B5: Papers differ in dataset, split, compression level, frame- vs video-level and metric (AUC vs accuracy). Treat the side-by-side as context, not a leaderboard. Say this to sir explicitly.
A6: Precision / recall | B6: Most deepfake papers report AUC or accuracy only; Precision/Recall/F1 exist only for our model in this comparison.
A7: Epsilon units | B7: Our eps is on a [0,1] pixel scale; papers use /255. 0.031 = 8/255, 0.063 = 16/255. Our eps 0.03 is the closest we ran to 8/255.
A8: README table check | B8: Old README table (Xception ~70.1%) was wrong/other protocol; the new README does not reuse it. Cite FF++ HQ per-manipulation numbers (92-98%) instead.
A9: Not fully verified | B9: Effort's 0.917 / 0.940 AUC and SBI's Celeb-DF 93.18 come from secondary summaries; FF++ accuracies come via Hussain et al. Table 1. Open the original tables to confirm before the presentation.
A10: Filename pattern | B10: prepare_data.py describes frames named like 01_02_outside_talking_still_laughing_YVGY8LOK_frame3.jpg; that naming looks like the DeepFakeDetection (DFD) part of FF++. Confirm exactly which FF++ subset and compression level we used and state it.
A11: Source: FF++ | B11: https://github.com/ondyari/FaceForensics ; arXiv:1901.08971
A12: Source: Adversarial Deepfakes | B12: https://arxiv.org/abs/2002.12749 ; WACV 2021 pp. 3348-3357
A13: Source: AFSL | B13: https://arxiv.org/abs/2403.08806
A14: Source: SBI | B14: https://arxiv.org/abs/2204.08376 ; https://github.com/mapooon/SelfBlendedImages
... A18: OPEN: run mismatch | B18: Two runs disagree (92.6% vs 80.1%). Confirm which split/checkpoint resnet18.pth is, then re-run test + attacks and refresh metrics.json, robustness csv and train_log.
